[2022-10-18 15:30:54,820] {taskinstance.py:1159} INFO - Dependencies all met for <TaskInstance: read_conf_from_gsheets_and_update_redis.read_from_gsheets_api scheduled__2022-10-18T15:20:00+00:00 [queued]>
[2022-10-18 15:30:54,826] {taskinstance.py:1159} INFO - Dependencies all met for <TaskInstance: read_conf_from_gsheets_and_update_redis.read_from_gsheets_api scheduled__2022-10-18T15:20:00+00:00 [queued]>
[2022-10-18 15:30:54,827] {taskinstance.py:1356} INFO - 
--------------------------------------------------------------------------------
[2022-10-18 15:30:54,829] {taskinstance.py:1357} INFO - Starting attempt 1 of 1
[2022-10-18 15:30:54,830] {taskinstance.py:1358} INFO - 
--------------------------------------------------------------------------------
[2022-10-18 15:30:54,898] {taskinstance.py:1377} INFO - Executing <Task(_PythonDecoratedOperator): read_from_gsheets_api> on 2022-10-18 15:20:00+00:00
[2022-10-18 15:30:54,902] {standard_task_runner.py:52} INFO - Started process 204 to run task
[2022-10-18 15:30:54,906] {standard_task_runner.py:79} INFO - Running: ['airflow', 'tasks', 'run', 'read_conf_from_gsheets_and_update_redis', 'read_from_gsheets_api', 'scheduled__2022-10-18T15:20:00+00:00', '--job-id', '3', '--raw', '--subdir', 'DAGS_FOLDER/read_conf_from_gsheets_api_and_update_redis.py', '--cfg-path', '/tmp/tmpn11zb157', '--error-file', '/tmp/tmp2ip_mgmy']
[2022-10-18 15:30:54,907] {standard_task_runner.py:80} INFO - Job 3: Subtask read_from_gsheets_api
[2022-10-18 15:30:54,936] {logging_mixin.py:115} WARNING - /root/.cache/pypoetry/virtualenvs/***-tXitOD5F-py3.8/lib/python3.8/site-packages/airflow/configuration.py:525 DeprecationWarning: The sql_alchemy_conn option in [core] has been moved to the sql_alchemy_conn option in [database] - the old setting has been used, but please update your config.
[2022-10-18 15:30:54,973] {task_command.py:370} INFO - Running <TaskInstance: read_conf_from_gsheets_and_update_redis.read_from_gsheets_api scheduled__2022-10-18T15:20:00+00:00 [running]> on host 6cdf6d517dc4
[2022-10-18 15:30:55,018] {taskinstance.py:1569} INFO - Exporting the following env vars:
AIRFLOW_CTX_DAG_EMAIL=wais@datakimia.com,david@datakimia.com,juanm@datakimia.com,tomas@datakimia.com
AIRFLOW_CTX_DAG_OWNER=atacana
AIRFLOW_CTX_DAG_ID=read_conf_from_gsheets_and_update_redis
AIRFLOW_CTX_TASK_ID=read_from_gsheets_api
AIRFLOW_CTX_EXECUTION_DATE=2022-10-18T15:20:00+00:00
AIRFLOW_CTX_TRY_NUMBER=1
AIRFLOW_CTX_DAG_RUN_ID=scheduled__2022-10-18T15:20:00+00:00
[2022-10-18 15:30:55,023] {taskinstance.py:1889} ERROR - Task failed with exception
Traceback (most recent call last):
  File "/root/.cache/pypoetry/virtualenvs/pharma-news-tXitOD5F-py3.8/lib/python3.8/site-packages/airflow/decorators/base.py", line 179, in execute
    return_value = super().execute(context)
  File "/root/.cache/pypoetry/virtualenvs/pharma-news-tXitOD5F-py3.8/lib/python3.8/site-packages/airflow/operators/python.py", line 171, in execute
    return_value = self.execute_callable()
  File "/root/.cache/pypoetry/virtualenvs/pharma-news-tXitOD5F-py3.8/lib/python3.8/site-packages/airflow/operators/python.py", line 189, in execute_callable
    return self.python_callable(*self.op_args, **self.op_kwargs)
  File "/etc/airflow/dags/read_conf_from_gsheets_api_and_update_redis.py", line 28, in read_from_gsheets_api
    return get_indication_keywords_conf()
  File "/news-project/pharma_news/helpers.py", line 229, in get_indication_keywords_conf
    conf_data = get_values_from_sheet_api(sheet_id, sheet_name)
  File "/news-project/pharma_news/helpers.py", line 195, in get_values_from_sheet_api
    creds, _ = google.auth.load_credentials_from_file(GOOGLE_SERVICE_ACCOUNT_DIR)
  File "/root/.cache/pypoetry/virtualenvs/pharma-news-tXitOD5F-py3.8/lib/python3.8/site-packages/google/auth/_default.py", line 119, in load_credentials_from_file
    raise exceptions.DefaultCredentialsError(
google.auth.exceptions.DefaultCredentialsError: File /news-project/service_account.json was not found.
[2022-10-18 15:30:55,035] {taskinstance.py:1395} INFO - Marking task as FAILED. dag_id=read_conf_from_gsheets_and_update_redis, task_id=read_from_gsheets_api, execution_date=20221018T152000, start_date=20221018T153054, end_date=20221018T153055
[2022-10-18 15:30:55,046] {logging_mixin.py:115} WARNING - /root/.cache/pypoetry/virtualenvs/***-tXitOD5F-py3.8/lib/python3.8/site-packages/airflow/utils/email.py:119 PendingDeprecationWarning: Fetching SMTP credentials from configuration variables will be deprecated in a future release. Please set credentials using a connection instead.
[2022-10-18 15:30:55,050] {email.py:228} INFO - Email alerting: attempt 1
[2022-10-18 15:30:55,187] {email.py:228} INFO - Email alerting: attempt 1
[2022-10-18 15:30:55,198] {taskinstance.py:1944} ERROR - Failed to send email to: ['wais@datakimia.com', 'david@datakimia.com', 'juanm@datakimia.com', 'tomas@datakimia.com']
Traceback (most recent call last):
  File "/root/.cache/pypoetry/virtualenvs/pharma-news-tXitOD5F-py3.8/lib/python3.8/site-packages/airflow/models/taskinstance.py", line 1451, in _run_raw_task
    self._execute_task_with_callbacks(context, test_mode)
  File "/root/.cache/pypoetry/virtualenvs/pharma-news-tXitOD5F-py3.8/lib/python3.8/site-packages/airflow/models/taskinstance.py", line 1598, in _execute_task_with_callbacks
    result = self._execute_task(context, task_orig)
  File "/root/.cache/pypoetry/virtualenvs/pharma-news-tXitOD5F-py3.8/lib/python3.8/site-packages/airflow/models/taskinstance.py", line 1659, in _execute_task
    result = execute_callable(context=context)
  File "/root/.cache/pypoetry/virtualenvs/pharma-news-tXitOD5F-py3.8/lib/python3.8/site-packages/airflow/decorators/base.py", line 179, in execute
    return_value = super().execute(context)
  File "/root/.cache/pypoetry/virtualenvs/pharma-news-tXitOD5F-py3.8/lib/python3.8/site-packages/airflow/operators/python.py", line 171, in execute
    return_value = self.execute_callable()
  File "/root/.cache/pypoetry/virtualenvs/pharma-news-tXitOD5F-py3.8/lib/python3.8/site-packages/airflow/operators/python.py", line 189, in execute_callable
    return self.python_callable(*self.op_args, **self.op_kwargs)
  File "/etc/airflow/dags/read_conf_from_gsheets_api_and_update_redis.py", line 28, in read_from_gsheets_api
    return get_indication_keywords_conf()
  File "/news-project/pharma_news/helpers.py", line 229, in get_indication_keywords_conf
    conf_data = get_values_from_sheet_api(sheet_id, sheet_name)
  File "/news-project/pharma_news/helpers.py", line 195, in get_values_from_sheet_api
    creds, _ = google.auth.load_credentials_from_file(GOOGLE_SERVICE_ACCOUNT_DIR)
  File "/root/.cache/pypoetry/virtualenvs/pharma-news-tXitOD5F-py3.8/lib/python3.8/site-packages/google/auth/_default.py", line 119, in load_credentials_from_file
    raise exceptions.DefaultCredentialsError(
google.auth.exceptions.DefaultCredentialsError: File /news-project/service_account.json was not found.

During handling of the above exception, another exception occurred:

Traceback (most recent call last):
  File "/root/.cache/pypoetry/virtualenvs/pharma-news-tXitOD5F-py3.8/lib/python3.8/site-packages/airflow/models/taskinstance.py", line 2326, in email_alert
    send_email(task.email, subject, html_content)
  File "/root/.cache/pypoetry/virtualenvs/pharma-news-tXitOD5F-py3.8/lib/python3.8/site-packages/airflow/utils/email.py", line 58, in send_email
    return backend(
  File "/root/.cache/pypoetry/virtualenvs/pharma-news-tXitOD5F-py3.8/lib/python3.8/site-packages/airflow/utils/email.py", line 119, in send_email_smtp
    send_mime_email(e_from=mail_from, e_to=recipients, mime_msg=msg, conn_id=conn_id, dryrun=dryrun)
  File "/root/.cache/pypoetry/virtualenvs/pharma-news-tXitOD5F-py3.8/lib/python3.8/site-packages/airflow/utils/email.py", line 230, in send_mime_email
    smtp_conn = _get_smtp_connection(smtp_host, smtp_port, smtp_timeout, smtp_ssl)
  File "/root/.cache/pypoetry/virtualenvs/pharma-news-tXitOD5F-py3.8/lib/python3.8/site-packages/airflow/utils/email.py", line 264, in _get_smtp_connection
    else smtplib.SMTP(host=host, port=port, timeout=timeout)
  File "/usr/local/lib/python3.8/smtplib.py", line 255, in __init__
    (code, msg) = self.connect(host, port)
  File "/usr/local/lib/python3.8/smtplib.py", line 339, in connect
    self.sock = self._get_socket(host, port, self.timeout)
  File "/usr/local/lib/python3.8/smtplib.py", line 310, in _get_socket
    return socket.create_connection((host, port), timeout,
  File "/usr/local/lib/python3.8/socket.py", line 787, in create_connection
    for res in getaddrinfo(host, port, 0, SOCK_STREAM):
  File "/usr/local/lib/python3.8/socket.py", line 918, in getaddrinfo
    for res in _socket.getaddrinfo(host, port, family, type, proto, flags):
socket.gaierror: [Errno -2] Name or service not known

During handling of the above exception, another exception occurred:

Traceback (most recent call last):
  File "/root/.cache/pypoetry/virtualenvs/pharma-news-tXitOD5F-py3.8/lib/python3.8/site-packages/airflow/models/taskinstance.py", line 1942, in handle_failure
    self.email_alert(error, task)
  File "/root/.cache/pypoetry/virtualenvs/pharma-news-tXitOD5F-py3.8/lib/python3.8/site-packages/airflow/models/taskinstance.py", line 2328, in email_alert
    send_email(task.email, subject, html_content_err)
  File "/root/.cache/pypoetry/virtualenvs/pharma-news-tXitOD5F-py3.8/lib/python3.8/site-packages/airflow/utils/email.py", line 58, in send_email
    return backend(
  File "/root/.cache/pypoetry/virtualenvs/pharma-news-tXitOD5F-py3.8/lib/python3.8/site-packages/airflow/utils/email.py", line 119, in send_email_smtp
    send_mime_email(e_from=mail_from, e_to=recipients, mime_msg=msg, conn_id=conn_id, dryrun=dryrun)
  File "/root/.cache/pypoetry/virtualenvs/pharma-news-tXitOD5F-py3.8/lib/python3.8/site-packages/airflow/utils/email.py", line 230, in send_mime_email
    smtp_conn = _get_smtp_connection(smtp_host, smtp_port, smtp_timeout, smtp_ssl)
  File "/root/.cache/pypoetry/virtualenvs/pharma-news-tXitOD5F-py3.8/lib/python3.8/site-packages/airflow/utils/email.py", line 264, in _get_smtp_connection
    else smtplib.SMTP(host=host, port=port, timeout=timeout)
  File "/usr/local/lib/python3.8/smtplib.py", line 255, in __init__
    (code, msg) = self.connect(host, port)
  File "/usr/local/lib/python3.8/smtplib.py", line 339, in connect
    self.sock = self._get_socket(host, port, self.timeout)
  File "/usr/local/lib/python3.8/smtplib.py", line 310, in _get_socket
    return socket.create_connection((host, port), timeout,
  File "/usr/local/lib/python3.8/socket.py", line 787, in create_connection
    for res in getaddrinfo(host, port, 0, SOCK_STREAM):
  File "/usr/local/lib/python3.8/socket.py", line 918, in getaddrinfo
    for res in _socket.getaddrinfo(host, port, family, type, proto, flags):
socket.gaierror: [Errno -2] Name or service not known
[2022-10-18 15:30:55,211] {standard_task_runner.py:92} ERROR - Failed to execute job 3 for task read_from_gsheets_api (File /news-project/service_account.json was not found.; 204)
[2022-10-18 15:30:55,247] {local_task_job.py:156} INFO - Task exited with return code 1
[2022-10-18 15:30:55,270] {local_task_job.py:273} INFO - 0 downstream tasks scheduled from follow-on schedule check
